{"summary":{"start_time":"2025-08-07T15:50:33.504128","end_time":"2025-08-07T15:52:54.446126","total_duration":140.94199800491333,"total_tests":0,"passed_tests":0,"failed_tests":0,"skipped_tests":0,"overall_success_rate":0,"test_suites_run":8},"test_suites":{"Database Models Unit Tests":{"name":"Database Models Unit Tests","path":"tests/unit/test_training_models.py","duration":0,"return_code":-1,"passed":0,"failed":0,"skipped":1,"errors":0,"total":1,"success_rate":0,"stdout":"","stderr":"Test file not found"},"Training Service Unit Tests":{"name":"Training Service Unit Tests","path":"tests/unit/test_training_service.py","duration":18.785557508468628,"return_code":2,"passed":0,"failed":0,"skipped":0,"errors":0,"total":0,"success_rate":0,"stdout":"============================= test session starts =============================\nplatform win32 -- Python 3.13.4, pytest-8.4.1, pluggy-1.6.0 -- C:\\Users\\mezac\\AppData\\Local\\Programs\\Python\\Python313\\python.exe\ncachedir: .pytest_cache\nrootdir: C:\\Users\\mezac\\Documents\\projects\\job\\Exam_Grader\nconfigfile: pytest.ini\nplugins: anyio-4.9.0, cov-6.2.1\ncollecting ... collected 0 items / 1 error\n\n=================================== ERRORS ====================================\n____________ ERROR collecting tests/unit/test_training_service.py _____________\n..\\..\\..\\..\\AppData\\Local\\Programs\\Python\\Python313\\Lib\\site-packages\\_pytest\\python.py:498: in importtestmodule\n    mod = import_path(\n..\\..\\..\\..\\AppData\\Local\\Programs\\Python\\Python313\\Lib\\site-packages\\_pytest\\pathlib.py:587: in import_path\n    importlib.import_module(module_name)\n..\\..\\..\\..\\AppData\\Local\\Programs\\Python\\Python313\\Lib\\importlib\\__init__.py:88: in import_module\n    return _bootstrap._gcd_import(name[level:], package, level)\n           ^^^^^^^^^^^^^^^^^^^^^^^^^^^^^^^^^^^^^^^^^^^^^^^^^^^^\n<frozen importlib._bootstrap>:1387: in _gcd_import\n    ???\n<frozen importlib._bootstrap>:1360: in _find_and_load\n    ???\n<frozen importlib._bootstrap>:1331: in _find_and_load_unlocked\n    ???\n<frozen importlib._bootstrap>:935: in _load_unlocked\n    ???\n..\\..\\..\\..\\AppData\\Local\\Programs\\Python\\Python313\\Lib\\site-packages\\_pytest\\assertion\\rewrite.py:186: in exec_module\n    exec(co, module.__dict__)\ntests\\unit\\test_training_service.py:14: in <module>\n    from src.services.training_service import TrainingService\nE     File \"C:\\Users\\mezac\\Documents\\projects\\job\\Exam_Grader\\src\\services\\training_service.py\", line 147\nE       def create_training_session(\nE                                   ^\nE   IndentationError: unindent does not match any outer indentation level\n------------------------------- Captured stderr -------------------------------\nWARNING - Migrated deprecated environment variable: DEEPSEEK_SEED -> DEEPSEEK_RANDOM_SEED\nINFO - Migrated 1 deprecated environment variables\nINFO - Configuration loaded successfully with no warnings\nWARNING - Generated temporary master key. Set SECRETS_MASTER_KEY environment variable for production.\nERROR - Failed to load secrets: \nINFO - Loaded processing configuration from config/processing.json\nINFO - Loaded processing configuration from config/processing.json\nINFO - Added log handler: file_handler\nINFO - Added log handler: error_file_handler\nINFO - Added log handler: metrics\nINFO - Log handlers configured from ProcessingConfigManager\nINFO - Registered fallback method 'tesseract_ocr' for operation 'ocr_processing' with priority 1\nINFO - Registered fallback method 'easyocr_fallback' for operation 'ocr_processing' with priority 2\nINFO - Registered fallback method 'basic_text_extraction' for operation 'ocr_processing' with priority 3\nINFO - Registered fallback method 'cached_response' for operation 'llm_processing' with priority 1\nINFO - Registered fallback method 'template_response' for operation 'llm_processing' with priority 2\nINFO - Registered fallback method 'rule_based_processing' for operation 'llm_processing' with priority 3\nINFO - Registered fallback method 'alternative_library' for operation 'file_processing' with priority 1\nINFO - Registered fallback method 'basic_text_read' for operation 'file_processing' with priority 2\nINFO - Registered fallback method 'keyword_matching' for operation 'mapping_service' with priority 1\nINFO - Registered fallback method 'simple_mapping' for operation 'mapping_service' with priority 2\nINFO - Registered fallback method 'cached_grading' for operation 'grading_service' with priority 1\nINFO - Registered fallback method 'rule_based_grading' for operation 'grading_service' with priority 2\nINFO - Registered fallback method 'length_based_grading' for operation 'grading_service' with priority 3\n============================== warnings summary ===============================\n..\\..\\..\\..\\AppData\\Local\\Programs\\Python\\Python313\\Lib\\site-packages\\PyPDF2\\__init__.py:21\n  C:\\Users\\mezac\\AppData\\Local\\Programs\\Python\\Python313\\Lib\\site-packages\\PyPDF2\\__init__.py:21: DeprecationWarning: PyPDF2 is deprecated. Please move to the pypdf library instead.\n    warnings.warn(\n\n<string>:9\n  <string>:9: DeprecationWarning: datetime.datetime.utcnow() is deprecated and scheduled for removal in a future version. Use timezone-aware objects to represent datetimes in UTC: datetime.datetime.now(datetime.UTC).\n\n-- Docs: https://docs.pytest.org/en/stable/how-to/capture-warnings.html\n=========================== short test summary info ===========================\nERROR tests/unit/test_training_service.py\n!!!!!!!!!!!!!!!!!!! Interrupted: 1 error during collection !!!!!!!!!!!!!!!!!!!!\n======================== 2 warnings, 1 error in 2.82s =========================\n","stderr":""},"Report Service Unit Tests":{"name":"Report Service Unit Tests","path":"tests/unit/test_training_report_service.py","duration":31.65838384628296,"return_code":1,"passed":0,"failed":0,"skipped":0,"errors":0,"total":0,"success_rate":0,"stdout":"============================= test session starts =============================\nplatform win32 -- Python 3.13.4, pytest-8.4.1, pluggy-1.6.0 -- C:\\Users\\mezac\\AppData\\Local\\Programs\\Python\\Python313\\python.exe\ncachedir: .pytest_cache\nrootdir: C:\\Users\\mezac\\Documents\\projects\\job\\Exam_Grader\nconfigfile: pytest.ini\nplugins: anyio-4.9.0, cov-6.2.1\ncollecting ... collected 19 items\n\ntests/unit/test_training_report_service.py::TestTrainingReportService::test_generate_markdown_report_success ERROR [  5%]\ntests/unit/test_training_report_service.py::TestTrainingReportService::test_generate_markdown_report_invalid_session ERROR [ 10%]\ntests/unit/test_training_report_service.py::TestTrainingReportService::test_generate_pdf_report_success ERROR [ 15%]\ntests/unit/test_training_report_service.py::TestTrainingReportService::test_generate_report_data ERROR [ 21%]\ntests/unit/test_training_report_service.py::TestTrainingReportService::test_calculate_statistics ERROR [ 26%]\ntests/unit/test_training_report_service.py::TestTrainingReportService::test_analyze_confidence_distribution ERROR [ 31%]\ntests/unit/test_training_report_service.py::TestTrainingReportService::test_analyze_question_types ERROR [ 36%]\ntests/unit/test_training_report_service.py::TestTrainingReportService::test_generate_performance_metrics ERROR [ 42%]\ntests/unit/test_training_report_service.py::TestTrainingReportService::test_create_confidence_chart_data ERROR [ 47%]\ntests/unit/test_training_report_service.py::TestTrainingReportService::test_create_question_type_chart_data ERROR [ 52%]\ntests/unit/test_training_report_service.py::TestTrainingReportService::test_format_duration ERROR [ 57%]\ntests/unit/test_training_report_service.py::TestTrainingReportService::test_format_file_size ERROR [ 63%]\ntests/unit/test_training_report_service.py::TestTrainingReportService::test_get_low_confidence_questions ERROR [ 68%]\ntests/unit/test_training_report_service.py::TestTrainingReportService::test_generate_recommendations ERROR [ 73%]\ntests/unit/test_training_report_service.py::TestTrainingReportService::test_export_report_json ERROR [ 78%]\ntests/unit/test_training_report_service.py::TestTrainingReportService::test_export_report_csv ERROR [ 84%]\ntests/unit/test_training_report_service.py::TestTrainingReportService::test_generate_chart_image ERROR [ 89%]\ntests/unit/test_training_report_service.py::TestTrainingReportService::test_validate_session_access ERROR [ 94%]\ntests/unit/test_training_report_service.py::TestTrainingReportService::test_get_report_metadata ERROR [100%]\n\n=================================== ERRORS ====================================\n_ ERROR at setup of TestTrainingReportService.test_generate_markdown_report_success _\nC:\\Users\\mezac\\Documents\\job\\Exam_Grader\\tests\\conftest.py:22: in app\n    ???\nwebapp\\app_factory.py:57: in create_app\n    _register_blueprints(app)\nwebapp\\app_factory.py:175: in _register_blueprints\n    from webapp.routes.training_routes import training_bp\nE     File \"C:\\Users\\mezac\\Documents\\projects\\job\\Exam_Grader\\webapp\\routes\\training_routes.py\", line 868\nE       test_submission_ids = data.get('test_submission_ids', [])\\n        \nE                                                                 ^\nE   SyntaxError: unexpected character after line continuation character\n---------------------------- Captured stderr setup ----------------------------\nINFO - Configuration loaded successfully with no warnings\nINFO - Loaded processing configuration from config/processing.json\nINFO - Retry configurations loaded from ProcessingConfigManager\nINFO - ServiceRegistry initialized\nINFO - Loaded processing configuration from config/processing.json\nINFO - Initialized LLM connection pool with 3 connections\nINFO - Using OpenAI library version: 1.93.3\nINFO - LLM service initialized successfully with model: deepseek-chat (test skipped)\nINFO - Consolidated OCR service initialized successfully\nINFO - Added data collector: system_health\nINFO - Added data collector: performance\nINFO - Added data collector: error_tracking\nINFO - Added dashboard: System Health\nINFO - Added dashboard: Performance Metrics\nINFO - Added dashboard: Error Tracking\nINFO - Loaded processing configuration from config/processing.json\nINFO - Configured notification channels: ['log', 'email', 'webhook']\nINFO - Enhanced alerting system initialized\nINFO - Loaded processing configuration from config/processing.json\nINFO - Added cache level: l1_memory (memory)\nINFO - Added cache level: l2_memory (memory)\nINFO - Added cache level: l3_disk (disk)\nINFO - Added cache level: l4_hybrid (hybrid)\nINFO - Cache levels configured from ProcessingConfigManager\nINFO - Started cache cleanup thread\nINFO - Loaded processing configuration from config/processing.json\nINFO - Real-time metrics collector initialized (interval: 120s)\n_ ERROR at setup of TestTrainingReportService.test_generate_markdown_report_invalid_session _\nC:\\Users\\mezac\\Documents\\job\\Exam_Grader\\tests\\conftest.py:22: in app\n    ???\nwebapp\\app_factory.py:57: in create_app\n    _register_blueprints(app)\nwebapp\\app_factory.py:175: in _register_blueprints\n    from webapp.routes.training_routes import training_bp\nE     File \"C:\\Users\\mezac\\Documents\\projects\\job\\Exam_Grader\\webapp\\routes\\training_routes.py\", line 868\nE       test_submission_ids = data.get('test_submission_ids', [])\\n        \nE                                                                 ^\nE   SyntaxError: unexpected character after line continuation character\n_ ERROR at setup of TestTrainingReportService.test_generate_pdf_report_success _\nC:\\Users\\mezac\\Documents\\job\\Exam_Grader\\tests\\conftest.py:22: in app\n    ???\nwebapp\\app_factory.py:57: in create_app\n    _register_blueprints(app)\nwebapp\\app_factory.py:175: in _register_blueprints\n    from webapp.routes.training_routes import training_bp\nE     File \"C:\\Users\\mezac\\Documents\\projects\\job\\Exam_Grader\\webapp\\routes\\training_routes.py\", line 868\nE       test_submission_ids = data.get('test_submission_ids', [])\\n        \nE                                                                 ^\nE   SyntaxError: unexpected character after line continuation character\n____ ERROR at setup of TestTrainingReportService.test_generate_report_data ____\nC:\\Users\\mezac\\Documents\\job\\Exam_Grader\\tests\\conftest.py:22: in app\n    ???\nwebapp\\app_factory.py:57: in create_app\n    _register_blueprints(app)\nwebapp\\app_factory.py:175: in _register_blueprints\n    from webapp.routes.training_routes import training_bp\nE     File \"C:\\Users\\mezac\\Documents\\projects\\job\\Exam_Grader\\webapp\\routes\\training_routes.py\", line 868\nE       test_submission_ids = data.get('test_submission_ids', [])\\n        \nE                                                                 ^\nE   SyntaxError: unexpected character after line continuation character\n____ ERROR at setup of TestTrainingReportService.test_calculate_statistics ____\nC:\\Users\\mezac\\Documents\\job\\Exam_Grader\\tests\\conftest.py:22: in app\n    ???\nwebapp\\app_factory.py:57: in create_app\n    _register_blueprints(app)\nwebapp\\app_factory.py:175: in _register_blueprints\n    from webapp.routes.training_routes import training_bp\nE     File \"C:\\Users\\mezac\\Documents\\projects\\job\\Exam_Grader\\webapp\\routes\\training_routes.py\", line 868\nE       test_submission_ids = data.get('test_submission_ids', [])\\n        \nE                                                                 ^\nE   SyntaxError: unexpected character after line continuation character\n_ ERROR at setup of TestTrainingReportService.test_analyze_confidence_distribution _\nC:\\Users\\mezac\\Documents\\job\\Exam_Grader\\tests\\conftest.py:22: in app\n    ???\nwebapp\\app_factory.py:57: in create_app\n    _register_blueprints(app)\nwebapp\\app_factory.py:175: in _register_blueprints\n    from webapp.routes.training_routes import training_bp\nE     File \"C:\\Users\\mezac\\Documents\\projects\\job\\Exam_Grader\\webapp\\routes\\training_routes.py\", line 868\nE       test_submission_ids = data.get('test_submission_ids', [])\\n        \nE                                                                 ^\nE   SyntaxError: unexpected character after line continuation character\n___ ERROR at setup of TestTrainingReportService.test_analyze_question_types ___\nC:\\Users\\mezac\\Documents\\job\\Exam_Grader\\tests\\conftest.py:22: in app\n    ???\nwebapp\\app_factory.py:57: in create_app\n    _register_blueprints(app)\nwebapp\\app_factory.py:175: in _register_blueprints\n    from webapp.routes.training_routes import training_bp\nE     File \"C:\\Users\\mezac\\Documents\\projects\\job\\Exam_Grader\\webapp\\routes\\training_routes.py\", line 868\nE       test_submission_ids = data.get('test_submission_ids', [])\\n        \nE                                                                 ^\nE   SyntaxError: unexpected character after line continuation character\n_ ERROR at setup of TestTrainingReportService.test_generate_performance_metrics _\nC:\\Users\\mezac\\Documents\\job\\Exam_Grader\\tests\\conftest.py:22: in app\n    ???\nwebapp\\app_factory.py:57: in create_app\n    _register_blueprints(app)\nwebapp\\app_factory.py:175: in _register_blueprints\n    from webapp.routes.training_routes import training_bp\nE     File \"C:\\Users\\mezac\\Documents\\projects\\job\\Exam_Grader\\webapp\\routes\\training_routes.py\", line 868\nE       test_submission_ids = data.get('test_submission_ids', [])\\n        \nE                                                                 ^\nE   SyntaxError: unexpected character after line continuation character\n_ ERROR at setup of TestTrainingReportService.test_create_confidence_chart_data _\nC:\\Users\\mezac\\Documents\\job\\Exam_Grader\\tests\\conftest.py:22: in app\n    ???\nwebapp\\app_factory.py:57: in create_app\n    _register_blueprints(app)\nwebapp\\app_factory.py:175: in _register_blueprints\n    from webapp.routes.training_routes import training_bp\nE     File \"C:\\Users\\mezac\\Documents\\projects\\job\\Exam_Grader\\webapp\\routes\\training_routes.py\", line 868\nE       test_submission_ids = data.get('test_submission_ids', [])\\n        \nE                                                                 ^\nE   SyntaxError: unexpected character after line continuation character\n_ ERROR at setup of TestTrainingReportService.test_create_question_type_chart_data _\nC:\\Users\\mezac\\Documents\\job\\Exam_Grader\\tests\\conftest.py:22: in app\n    ???\nwebapp\\app_factory.py:57: in create_app\n    _register_blueprints(app)\nwebapp\\app_factory.py:175: in _register_blueprints\n    from webapp.routes.training_routes import training_bp\nE     File \"C:\\Users\\mezac\\Documents\\projects\\job\\Exam_Grader\\webapp\\routes\\training_routes.py\", line 868\nE       test_submission_ids = data.get('test_submission_ids', [])\\n        \nE                                                                 ^\nE   SyntaxError: unexpected character after line continuation character\n______ ERROR at setup of TestTrainingReportService.test_format_duration _______\nC:\\Users\\mezac\\Documents\\job\\Exam_Grader\\tests\\conftest.py:22: in app\n    ???\nwebapp\\app_factory.py:57: in create_app\n    _register_blueprints(app)\nwebapp\\app_factory.py:175: in _register_blueprints\n    from webapp.routes.training_routes import training_bp\nE     File \"C:\\Users\\mezac\\Documents\\projects\\job\\Exam_Grader\\webapp\\routes\\training_routes.py\", line 868\nE       test_submission_ids = data.get('test_submission_ids', [])\\n        \nE                                                                 ^\nE   SyntaxError: unexpected character after line continuation character\n______ ERROR at setup of TestTrainingReportService.test_format_file_size ______\nC:\\Users\\mezac\\Documents\\job\\Exam_Grader\\tests\\conftest.py:22: in app\n    ???\nwebapp\\app_factory.py:57: in create_app\n    _register_blueprints(app)\nwebapp\\app_factory.py:175: in _register_blueprints\n    from webapp.routes.training_routes import training_bp\nE     File \"C:\\Users\\mezac\\Documents\\projects\\job\\Exam_Grader\\webapp\\routes\\training_routes.py\", line 868\nE       test_submission_ids = data.get('test_submission_ids', [])\\n        \nE                                                                 ^\nE   SyntaxError: unexpected character after line continuation character\n_ ERROR at setup of TestTrainingReportService.test_get_low_confidence_questions _\nC:\\Users\\mezac\\Documents\\job\\Exam_Grader\\tests\\conftest.py:22: in app\n    ???\nwebapp\\app_factory.py:57: in create_app\n    _register_blueprints(app)\nwebapp\\app_factory.py:175: in _register_blueprints\n    from webapp.routes.training_routes import training_bp\nE     File \"C:\\Users\\mezac\\Documents\\projects\\job\\Exam_Grader\\webapp\\routes\\training_routes.py\", line 868\nE       test_submission_ids = data.get('test_submission_ids', [])\\n        \nE                                                                 ^\nE   SyntaxError: unexpected character after line continuation character\n__ ERROR at setup of TestTrainingReportService.test_generate_recommendations __\nC:\\Users\\mezac\\Documents\\job\\Exam_Grader\\tests\\conftest.py:22: in app\n    ???\nwebapp\\app_factory.py:57: in create_app\n    _register_blueprints(app)\nwebapp\\app_factory.py:175: in _register_blueprints\n    from webapp.routes.training_routes import training_bp\nE     File \"C:\\Users\\mezac\\Documents\\projects\\job\\Exam_Grader\\webapp\\routes\\training_routes.py\", line 868\nE       test_submission_ids = data.get('test_submission_ids', [])\\n        \nE                                                                 ^\nE   SyntaxError: unexpected character after line continuation character\n_____ ERROR at setup of TestTrainingReportService.test_export_report_json _____\nC:\\Users\\mezac\\Documents\\job\\Exam_Grader\\tests\\conftest.py:22: in app\n    ???\nwebapp\\app_factory.py:57: in create_app\n    _register_blueprints(app)\nwebapp\\app_factory.py:175: in _register_blueprints\n    from webapp.routes.training_routes import training_bp\nE     File \"C:\\Users\\mezac\\Documents\\projects\\job\\Exam_Grader\\webapp\\routes\\training_routes.py\", line 868\nE       test_submission_ids = data.get('test_submission_ids', [])\\n        \nE                                                                 ^\nE   SyntaxError: unexpected character after line continuation character\n_____ ERROR at setup of TestTrainingReportService.test_export_report_csv ______\nC:\\Users\\mezac\\Documents\\job\\Exam_Grader\\tests\\conftest.py:22: in app\n    ???\nwebapp\\app_factory.py:57: in create_app\n    _register_blueprints(app)\nwebapp\\app_factory.py:175: in _register_blueprints\n    from webapp.routes.training_routes import training_bp\nE     File \"C:\\Users\\mezac\\Documents\\projects\\job\\Exam_Grader\\webapp\\routes\\training_routes.py\", line 868\nE       test_submission_ids = data.get('test_submission_ids', [])\\n        \nE                                                                 ^\nE   SyntaxError: unexpected character after line continuation character\n____ ERROR at setup of TestTrainingReportService.test_generate_chart_image ____\nC:\\Users\\mezac\\Documents\\job\\Exam_Grader\\tests\\conftest.py:22: in app\n    ???\nwebapp\\app_factory.py:57: in create_app\n    _register_blueprints(app)\nwebapp\\app_factory.py:175: in _register_blueprints\n    from webapp.routes.training_routes import training_bp\nE     File \"C:\\Users\\mezac\\Documents\\projects\\job\\Exam_Grader\\webapp\\routes\\training_routes.py\", line 868\nE       test_submission_ids = data.get('test_submission_ids', [])\\n        \nE                                                                 ^\nE   SyntaxError: unexpected character after line continuation character\n__ ERROR at setup of TestTrainingReportService.test_validate_session_access ___\nC:\\Users\\mezac\\Documents\\job\\Exam_Grader\\tests\\conftest.py:22: in app\n    ???\nwebapp\\app_factory.py:57: in create_app\n    _register_blueprints(app)\nwebapp\\app_factory.py:175: in _register_blueprints\n    from webapp.routes.training_routes import training_bp\nE     File \"C:\\Users\\mezac\\Documents\\projects\\job\\Exam_Grader\\webapp\\routes\\training_routes.py\", line 868\nE       test_submission_ids = data.get('test_submission_ids', [])\\n        \nE                                                                 ^\nE   SyntaxError: unexpected character after line continuation character\n____ ERROR at setup of TestTrainingReportService.test_get_report_metadata _____\nC:\\Users\\mezac\\Documents\\job\\Exam_Grader\\tests\\conftest.py:22: in app\n    ???\nwebapp\\app_factory.py:57: in create_app\n    _register_blueprints(app)\nwebapp\\app_factory.py:175: in _register_blueprints\n    from webapp.routes.training_routes import training_bp\nE     File \"C:\\Users\\mezac\\Documents\\projects\\job\\Exam_Grader\\webapp\\routes\\training_routes.py\", line 868\nE       test_submission_ids = data.get('test_submission_ids', [])\\n        \nE                                                                 ^\nE   SyntaxError: unexpected character after line continuation character\n============================== warnings summary ===============================\n..\\..\\..\\..\\AppData\\Local\\Programs\\Python\\Python313\\Lib\\site-packages\\PyPDF2\\__init__.py:21\n  C:\\Users\\mezac\\AppData\\Local\\Programs\\Python\\Python313\\Lib\\site-packages\\PyPDF2\\__init__.py:21: DeprecationWarning: PyPDF2 is deprecated. Please move to the pypdf library instead.\n    warnings.warn(\n\n<string>:9\n  <string>:9: DeprecationWarning: datetime.datetime.utcnow() is deprecated and scheduled for removal in a future version. Use timezone-aware objects to represent datetimes in UTC: datetime.datetime.now(datetime.UTC).\n\n-- Docs: https://docs.pytest.org/en/stable/how-to/capture-warnings.html\n=============================== tests coverage ================================\n_______________ coverage: platform win32, python 3.13.4-final-0 _______________\n\nName                                             Stmts   Miss  Cover   Missing\n------------------------------------------------------------------------------\nsrc\\__init__.py                                      6      0   100%\nsrc\\api\\__init__.py                                  1      1     0%   9\nsrc\\api\\unified_api.py                             237    237     0%   8-587\nsrc\\config\\__init__.py                               1      0   100%\nsrc\\config\\config_manager.py                        69     69     0%   1-172\nsrc\\config\\config_utils.py                         121    121     0%   3-333\nsrc\\config\\demo_config.py                           81     81     0%   8-120\nsrc\\config\\logging_config.py                         2      2     0%   1-2\nsrc\\config\\processing_config.py                    244     96    61%   17-20, 36, 55, 71, 97, 140, 160, 164, 178, 196, 229-236, 254, 256, 261-270, 277-285, 290-295, 302-307, 314-321, 355-356, 461-464, 481-487, 495, 499, 505, 513, 521-523, 532-580, 592-629\nsrc\\config\\unified_config.py                       264     54    80%   21-24, 31, 61, 77, 124, 131, 179, 183, 200, 217, 233, 279, 284, 289, 306-310, 314, 330-334, 400, 404, 478-479, 488-491, 518-521, 586, 589, 605-613, 622, 663-677, 689-728\nsrc\\constants.py                                    88      0   100%\nsrc\\database\\__init__.py                            11      4    64%   24-25, 30-31\nsrc\\database\\migrations.py                          71     60    15%   16-17, 21-46, 50-67, 71-121, 125-137\nsrc\\database\\models.py                             488     78    84%   73, 77-79, 83, 87, 91-92, 96-97, 102, 106, 110, 114, 155, 216, 261, 311, 346, 350-351, 355, 359, 403, 450, 512, 584, 661, 743-745, 750-753, 757-763, 767-774, 778-784, 788-795, 799, 817-822, 827, 896, 970, 1031, 1083, 1131, 1180\nsrc\\database\\optimization_utils.py                 104    104     0%   3-376\nsrc\\database\\optimized_models.py                   306    112    63%   63-68, 72-81, 134-142, 147-151, 155-159, 163, 167, 171-174, 178-179, 184-186, 192-220, 225, 229, 233, 283-287, 292-296, 301-312, 316-319, 326, 330, 411-414, 419-423, 428-432, 437-441, 445-448, 455-464, 468, 526, 596, 641, 645-648, 652, 656, 729-732, 737-741, 745\nsrc\\database\\progress_models.py                    105    105     0%   3-257\nsrc\\database\\schema_migrations.py                  117    117     0%   3-530\nsrc\\database\\sqlite_optimizations.py                95     95     0%   8-208\nsrc\\database\\utils.py                              132     98    26%   18-32, 44-82, 87-103, 116-145, 152-158, 165-175, 182-194, 202-215, 220-226\nsrc\\exceptions\\__init__.py                           3      0   100%\nsrc\\exceptions\\application_errors.py               104     66    37%   54-73, 80-91, 97-99, 103, 120, 152-156, 171, 187-191, 211-217, 232-236, 251-255, 273, 290-294, 309-313, 334-340, 361-367\nsrc\\exceptions\\enhanced_error_handler.py           140    140     0%   3-527\nsrc\\exceptions\\error_mapper.py                     102    102     0%   3-542\nsrc\\exceptions\\error_tracker.py                    183    144    21%   30, 51-63, 85-123, 132-135, 143-144, 155-159, 181-203, 214-255, 274-294, 320-341, 352-370, 375-384, 388-406, 418, 429-443, 465-504, 518-520, 542\nsrc\\exceptions\\flask_error_integration.py          140    140     0%   3-456\nsrc\\logging\\__init__.py                             52     13    75%   91-95, 107-111, 123-127\nsrc\\logging\\comprehensive_logger.py                268    193    28%   25-28, 60, 103-144, 149-214, 218, 225, 232, 239-267, 271-286, 292-295, 299-300, 304-307, 317-351, 362, 366, 370, 374, 384-399, 409-424, 428, 432, 436-441, 460-462, 468-480, 489-526, 533-534, 540-552, 558-568, 577-586, 593, 599-609, 623-634, 642-646, 667-678, 703-736\nsrc\\logging\\config.py                              120     99    18%   16-23, 56-77, 85-143, 165-185, 196-203, 216-223, 231-257, 265, 303-324, 336-338, 352-354, 363-365\nsrc\\logging\\flask_integration.py                   249    215    14%   18-27, 33-40, 69-97, 106-122, 133, 141-143, 151-159, 167-169, 180-186, 194, 209-219, 223-269, 291-361, 372-411, 426-472, 483-521, 535-537, 545, 553-581, 602-675, 688-768, 794-803\nsrc\\logging\\log_aggregator.py                      249    199    20%   60, 109-113, 139-169, 173-179, 189-195, 201-276, 281-295, 306-309, 320-330, 348-364, 368-390, 394-395, 407, 422-486, 497-584, 588-597, 617-666\nsrc\\logging\\structured_logger.py                   230    148    36%   78-79, 83, 95-98, 126-188, 211-237, 241-246, 254, 258, 269-299, 310-316, 325-326, 335-336, 345-346, 355-356, 366-367, 377-378, 387-389, 398-399, 418-423, 442-449, 474-496, 513-524, 549-555, 572-583, 591-592, 596-597, 614, 631, 645, 650\nsrc\\models\\__init__.py                               4      0   100%\nsrc\\models\\api_responses.py                        133     43    68%   47, 67-72, 87-99, 103, 108, 115, 128-132, 150, 164-168, 188-191, 204-206, 228-232, 244, 254, 259, 264, 269, 279, 286, 293, 300, 309\nsrc\\models\\document_models.py                       50      0   100%\nsrc\\models\\validation.py                           111     61    45%   29-41, 61-70, 81-89, 93, 97, 101, 105, 109, 120, 125, 134-141, 146-154, 159-167, 174-182, 189-197, 202-213, 220-230, 237-247, 262-280\nsrc\\parsing\\__init__.py                              1      1     0%   25\nsrc\\parsing\\parse_guide.py                          54     54     0%   8-108\nsrc\\parsing\\parse_submission.py                    223    223     0%   21-495\nsrc\\parsing\\pdf_helper.py                           52     52     0%   5-116\nsrc\\performance\\query_cache.py                     119     79    34%   17-19, 41-47, 51-53, 57-66, 70-77, 81-92, 96-107, 111-115, 119-120, 124-125, 150-170, 186-198, 203, 208-209, 224-237\nsrc\\security\\__init__.py                             0      0   100%\nsrc\\security\\auth_system.py                        282    282     0%   7-696\nsrc\\security\\enhanced_input_validator.py           241    241     0%   7-592\nsrc\\security\\flask_session_interface.py             97     97     0%   1-166\nsrc\\security\\secrets_manager.py                    179    114    36%   21-24, 62-64, 69, 73, 116-119, 132-136, 145-165, 179-194, 207-220, 232-244, 253-265, 277-297, 309-320, 332-351, 363-375, 385-399\nsrc\\security\\secure_file_service.py                206    206     0%   7-530\nsrc\\security\\security_config.py                    330    330     0%   7-663\nsrc\\security\\security_middleware.py                259    259     0%   11-678\nsrc\\security\\security_utils.py                     114    114     0%   11-358\nsrc\\security\\session_manager.py                    210    210     0%   9-466\nsrc\\services\\__init__.py                             9      0   100%\nsrc\\services\\base_service.py                       217    131    40%   43-45, 50, 59-66, 70, 137, 141, 145-146, 161-210, 214-219, 229-256, 260-261, 264, 295-302, 314-315, 324-325, 335-339, 351-352, 361-378, 387-400, 405-408, 422-433, 444-451\nsrc\\services\\cache_manager.py                      398    255    36%   53-55, 59-60, 77-78, 83, 116-168, 172-208, 212-216, 220-228, 236-237, 240-241, 246, 252-253, 274-285, 289-332, 336-363, 367-374, 378-385, 389-398, 402-407, 411, 415-416, 440, 502-505, 509-537, 550-551, 558-563, 567-581, 591-617, 621-631, 635-641, 651, 657-678, 682-695, 700, 711-717, 725-727, 731\nsrc\\services\\confidence_monitor.py                 298    298     0%   8-624\nsrc\\services\\consolidated_grading_service.py       252    220    13%   38-51, 55-79, 83-90, 94-102, 106, 110-121, 125-133, 153-195, 201-232, 236-258, 264-283, 289-343, 349-404, 409-427, 431-435, 439-444, 448-500, 516-529, 544-553, 559-566, 572-599, 609, 625-627\nsrc\\services\\consolidated_llm_service.py           543    394    27%   45-48, 52-54, 69-86, 90-93, 97-120, 146-148, 152-162, 168-172, 240-254, 260-262, 268-273, 279-295, 301-303, 309-311, 319, 323-360, 364-392, 396, 505-506, 510-511, 521-522, 533-534, 547-579, 588-591, 595-635, 639-647, 651-662, 666-688, 692, 696-710, 714-726, 730-740, 744-753, 763-802, 806-1015, 1023-1060, 1064-1107, 1111-1158, 1162-1167, 1171-1180\nsrc\\services\\consolidated_mapping_service.py       293    265    10%   33-46, 50-74, 78-85, 89-98, 102, 106-117, 121-129, 133-183, 187-230, 234-328, 332-369, 373-424, 429-459, 463-488, 497-536, 542-592, 598-645, 649, 660-663\nsrc\\services\\consolidated_ocr_service.py           503    409    19%   22-24, 30-32, 38-40, 56-59, 63-65, 96, 136-138, 141-145, 155-164, 172-180, 184-191, 197-198, 200-201, 233-235, 246-256, 260-264, 268-288, 292-301, 305-317, 321-352, 366-435, 442-490, 497-505, 509-558, 563-575, 580-617, 627-646, 652-657, 661-662, 668-679, 683-710, 714-723, 734-761, 765-789, 793-810, 814-839, 844-863, 867-886, 890-897, 901\nsrc\\services\\content_validator.py                  274    274     0%   9-566\nsrc\\services\\core\\__init__.py                        3      0   100%\nsrc\\services\\core\\error_service.py                 238    158    34%   77-78, 92-98, 102, 128-135, 139-143, 147-152, 156-184, 194-248, 261-323, 332-378, 382-443, 447-451, 457-510, 524, 530-552, 558-578, 582-587, 607-621\nsrc\\services\\core\\file_processing_service.py       169    140    17%   36-46, 50-55, 59-62, 66-87, 91-103, 107-124, 128-141, 145-165, 169-197, 201-231, 235, 246, 258-262\nsrc\\services\\core_service.py                       503    431    14%   38-39, 85-234, 238-251, 255-268, 272-296, 300-329, 333-346, 351-424, 428-456, 460, 488-602, 608-656, 662-718, 722-737, 743-802, 806-838, 850-922, 926, 930-947, 951-985, 989-1015, 1019, 1037, 1059-1072, 1076, 1084, 1091-1138\nsrc\\services\\diagnostic_collector.py               217    217     0%   8-523\nsrc\\services\\direct_llm_guide_processor.py         247    247     0%   8-686\nsrc\\services\\enhanced_alerting_system.py           268    171    36%   62-78, 169, 207, 211-223, 227-234, 238-253, 257-287, 291-332, 336-363, 367-417, 428-459, 470-486, 496-500, 511, 522, 532-539, 543-560, 564, 568-574, 596-602, 606-607\nsrc\\services\\enhanced_logging_service.py           220     98    55%   69, 86, 111-113, 119, 151, 158-180, 194-221, 225-226, 253, 272-275, 279-292, 302-307, 311, 329-358, 369, 380, 391, 402-405, 417-420, 424-432, 448-456, 459-469, 472-487, 514\nsrc\\services\\enhanced_result_service.py            299    272     9%   40-96, 100-128, 134-190, 196-239, 243-262, 274-340, 346-369, 390-418, 424-454, 460-523, 528-535, 539-546, 550-581, 585-587, 591-597, 601-608, 612-637, 641-666\nsrc\\services\\error_monitor.py                      275    275     0%   8-667\nsrc\\services\\error_recovery.py                     152    152     0%   8-449\nsrc\\services\\extraction_method_registry.py         279    279     0%   9-735\nsrc\\services\\fallback_manager.py                   348    261    25%   206-226, 234-260, 269-351, 361-454, 463-477, 481-495, 499-529, 535-539, 545-555, 559-569, 573-577, 581-589, 594-603, 608-614, 618-631, 635-640, 647-667, 674-692, 696-704, 708-724, 735-747, 756-781, 785-794, 800-809, 815-816, 820-824\nsrc\\services\\file_cleanup_service.py               243    243     0%   7-493\nsrc\\services\\file_processing_service.py            564    564     0%   8-1349\nsrc\\services\\guide_processing_router.py            151    151     0%   8-386\nsrc\\services\\monitoring\\__init__.py                  2      0   100%\nsrc\\services\\monitoring\\monitoring_service.py      243    163    33%   105-112, 116-120, 124-131, 140-155, 159-163, 167-217, 221-222, 226-269, 293-306, 312-331, 335-365, 369-377, 387-409, 413-414, 418-428, 432-437, 441-455, 459-461, 484-492, 496-500\nsrc\\services\\monitoring_dashboard.py               263    141    46%   74, 97-98, 105, 114-121, 131-156, 170-195, 208-230, 377-381, 385, 389, 408-412, 416-448, 452-458, 463-497, 501-507, 512-522, 526-527, 531-537, 541-548, 552-566, 570-595, 599\nsrc\\services\\monitoring_service_manager.py          55     55     0%   7-91\nsrc\\services\\performance_optimizer.py              377    377     0%   8-699\nsrc\\services\\processing_error_handler.py           191    191     0%   8-542\nsrc\\services\\realtime_metrics_collector.py         236    138    42%   47, 66-69, 73, 77-83, 87-90, 94-112, 278-282, 286, 290-294, 298-318, 322-327, 333-341, 345-351, 355-373, 377-402, 406-423, 427-452, 456-494, 498-508, 512-537, 547-550\nsrc\\services\\realtime_service.py                   135    104    23%   13, 31, 35-47, 52-92, 96-120, 124-134, 140-155, 161-176, 182-198, 204-211, 222-230, 241-249, 253-258, 268-275, 287-290, 302-305, 313-315, 324-325, 339-340\nsrc\\services\\resource_optimizer.py                 299    299     0%   8-654\nsrc\\services\\resource_validator.py                 182    182     0%   8-689\nsrc\\services\\retry_manager.py                      271    193    29%   144-149, 154, 225-226, 249-373, 393-523, 537-559, 563-570, 574-631, 635-647, 651-681, 687-689, 695-720, 726, 730-748, 752-758, 762-763, 772-785, 794-807\nsrc\\services\\secure_file_handler.py                166    166     0%   7-318\nsrc\\services\\service_registry.py                   192    138    28%   98-141, 153-155, 159-161, 174-188, 200-217, 229-273, 277-289, 304-313, 317-328, 332-366, 370-372, 377-391, 396-400, 404-408\nsrc\\services\\service_shutdown_manager.py           214    214     0%   8-409\nsrc\\services\\training_report_pdf.py                185    165    11%   21, 37-72, 77-104, 109-177, 181-232, 236-242, 272-298, 302-306, 335, 479-504, 508-529, 533-562, 566-598, 602-622\nsrc\\services\\training_report_service.py            631    557    12%   37-38, 68-82, 86-94, 98-111, 115-118, 130-154, 166-204, 216-239, 251-281, 293-327, 339-382, 394-438, 451-500, 512-547, 559-602, 606-610, 622-642, 654-683, 697-744, 748-793, 797-844, 848-891, 895-948, 952-1007, 1011-1082, 1086-1134, 1149-1181, 1185-1205, 1209-1227, 1231-1257, 1261-1288, 1292-1326, 1330-1350, 1354-1383, 1387-1392, 1405-1439, 1452-1471, 1487-1509\nsrc\\services\\training_visualization_service.py     187    187     0%   7-337\nsrc\\services\\ultra_fast_processing.py              319    319     0%   13-663\nsrc\\services\\websocket_manager.py                  369    297    20%   25, 66, 103-142, 150-153, 158-314, 325-335, 343-353, 365-385, 397-401, 413-428, 448-474, 494-531, 548-558, 571-581, 589-640, 645-659, 663-694, 698-719, 730-731, 742-743, 754-755, 763-773, 781, 789, 800, 809-813, 822-832\nsrc\\utils\\__init__.py                                2      2     0%   3-9\nsrc\\utils\\circuit_breaker.py                        95     95     0%   8-237\nsrc\\utils\\content_deduplication.py                  42     42     0%   3-116\nsrc\\utils\\health_check.py                          145    145     0%   8-379\nsrc\\utils\\input_validator.py                       140    140     0%   8-471\nsrc\\utils\\logging_config.py                        116    116     0%   8-370\nsrc\\utils\\response_utils.py                        120    120     0%   3-357\nsrc\\utils\\validation_utils.py                      159    159     0%   7-532\nwebapp\\__init__.py                                   4      0   100%\nwebapp\\api\\__init__.py                               6      6     0%   8-17\nwebapp\\api\\error_handlers.py                       121    121     0%   8-376\nwebapp\\api\\middleware.py                           117    117     0%   8-304\nwebapp\\api\\monitoring_api.py                       175    175     0%   8-464\nwebapp\\api\\status_api.py                           231    231     0%   8-543\nwebapp\\api\\unified_api.py                          196    196     0%   8-631\nwebapp\\app.py                                       29     29     0%   8-68\nwebapp\\app_factory.py                              174    114    34%   60-73, 89-116, 139, 177-198, 203-219, 224-229, 234-245, 250-278, 283-302, 307-313, 318-346\nwebapp\\error_handlers.py                            38     38     0%   7-231\nwebapp\\forms.py                                     13     13     0%   1-31\nwebapp\\routes\\__init__.py                            0      0   100%\nwebapp\\routes\\admin_routes.py                      153    101    34%   28-31, 41-76, 90-99, 107-146, 156, 164-176, 184-192, 200-235, 243-271, 282-309, 317-345\nwebapp\\routes\\auth_routes.py                       137    116    15%   21-86, 92, 98-151, 158-167, 174, 181-217\nwebapp\\routes\\guide_processing_routes.py           287    260     9%   30-113, 121-178, 183-376, 381-474, 479-596, 603-632, 639-657, 664-698\nwebapp\\routes\\main_routes.py                      1053    929    12%   38-40, 62-125, 156-208, 232-259, 282-476, 498-783, 807-826, 833-931, 963-970, 977-997, 1004-1030, 1037-1105, 1115-1188, 1195-1233, 1240-1253, 1263-1291, 1301-1338, 1348-1390, 1397-1429, 1439-1475, 1485-1525, 1532-1805, 1812-1843, 1850-1969, 1976-1993, 2000-2069, 2079-2175, 2182-2217, 2224-2282, 2289-2326, 2333-2487, 2501-2506, 2511-2547, 2552-2581, 2586-2615, 2620-2626, 2633-2708, 2715-2748, 2755-2786, 2793-2799, 2805-2823, 2831-2845\nwebapp\\routes\\monitoring.py                        101    101     0%   5-183\nwebapp\\routes\\monitoring_routes.py                 106     73    31%   27-41, 50-55, 62-67, 74-79, 86-91, 97-110, 116-129, 135-153, 159-160, 165-166\nwebapp\\routes\\processing_routes.py                 228    185    19%   27-34, 41-72, 96-161, 168-213, 223, 230-293, 300-448, 455-537, 561-597, 604-633, 643-687\nwebapp\\routes\\training_websocket.py                205    205     0%   7-526\nwebapp\\security.py                                  98     98     0%   7-277\nwebapp\\security_middleware.py                       17     17     0%   1-55\n------------------------------------------------------------------------------\nTOTAL                                            22836  18994    17%\n=========================== short test summary info ===========================\nERROR tests/unit/test_training_report_service.py::TestTrainingReportService::test_generate_markdown_report_success\nERROR tests/unit/test_training_report_service.py::TestTrainingReportService::test_generate_markdown_report_invalid_session\nERROR tests/unit/test_training_report_service.py::TestTrainingReportService::test_generate_pdf_report_success\nERROR tests/unit/test_training_report_service.py::TestTrainingReportService::test_generate_report_data\nERROR tests/unit/test_training_report_service.py::TestTrainingReportService::test_calculate_statistics\nERROR tests/unit/test_training_report_service.py::TestTrainingReportService::test_analyze_confidence_distribution\nERROR tests/unit/test_training_report_service.py::TestTrainingReportService::test_analyze_question_types\nERROR tests/unit/test_training_report_service.py::TestTrainingReportService::test_generate_performance_metrics\nERROR tests/unit/test_training_report_service.py::TestTrainingReportService::test_create_confidence_chart_data\nERROR tests/unit/test_training_report_service.py::TestTrainingReportService::test_create_question_type_chart_data\nERROR tests/unit/test_training_report_service.py::TestTrainingReportService::test_format_duration\nERROR tests/unit/test_training_report_service.py::TestTrainingReportService::test_format_file_size\nERROR tests/unit/test_training_report_service.py::TestTrainingReportService::test_get_low_confidence_questions\nERROR tests/unit/test_training_report_service.py::TestTrainingReportService::test_generate_recommendations\nERROR tests/unit/test_training_report_service.py::TestTrainingReportService::test_export_report_json\nERROR tests/unit/test_training_report_service.py::TestTrainingReportService::test_export_report_csv\nERROR tests/unit/test_training_report_service.py::TestTrainingReportService::test_generate_chart_image\nERROR tests/unit/test_training_report_service.py::TestTrainingReportService::test_validate_session_access\nERROR tests/unit/test_training_report_service.py::TestTrainingReportService::test_get_report_metadata\n======================= 2 warnings, 19 errors in 19.08s =======================\n","stderr":"C:\\Users\\mezac\\AppData\\Local\\Programs\\Python\\Python313\\Lib\\site-packages\\coverage\\report_core.py:110: CoverageWarning: Couldn't parse Python file 'C:\\Users\\mezac\\Documents\\projects\\job\\Exam_Grader\\src\\services\\training_service.py' (couldnt-parse)\n  coverage._warn(msg, slug=\"couldnt-parse\")\nC:\\Users\\mezac\\AppData\\Local\\Programs\\Python\\Python313\\Lib\\site-packages\\coverage\\report_core.py:110: CoverageWarning: Couldn't parse Python file 'C:\\Users\\mezac\\Documents\\projects\\job\\Exam_Grader\\webapp\\routes\\training_routes.py' (couldnt-parse)\n  coverage._warn(msg, slug=\"couldnt-parse\")\n"},"Integration Tests":{"name":"Integration Tests","path":"tests/integration/test_training_integration.py","duration":0,"return_code":-1,"passed":0,"failed":0,"skipped":1,"errors":0,"total":1,"success_rate":0,"stdout":"","stderr":"Test file not found"},"System Tests":{"name":"System Tests","path":"tests/system/test_training_system.py","duration":13.099426746368408,"return_code":2,"passed":0,"failed":0,"skipped":0,"errors":0,"total":0,"success_rate":0,"stdout":"============================= test session starts =============================\nplatform win32 -- Python 3.13.4, pytest-8.4.1, pluggy-1.6.0 -- C:\\Users\\mezac\\AppData\\Local\\Programs\\Python\\Python313\\python.exe\ncachedir: .pytest_cache\nrootdir: C:\\Users\\mezac\\Documents\\projects\\job\\Exam_Grader\nconfigfile: pytest.ini\nplugins: anyio-4.9.0, cov-6.2.1\ncollecting ... collected 0 items / 1 error\n\n=================================== ERRORS ====================================\n____________ ERROR collecting tests/system/test_training_system.py ____________\n..\\..\\..\\..\\AppData\\Local\\Programs\\Python\\Python313\\Lib\\site-packages\\_pytest\\python.py:498: in importtestmodule\n    mod = import_path(\n..\\..\\..\\..\\AppData\\Local\\Programs\\Python\\Python313\\Lib\\site-packages\\_pytest\\pathlib.py:587: in import_path\n    importlib.import_module(module_name)\n..\\..\\..\\..\\AppData\\Local\\Programs\\Python\\Python313\\Lib\\importlib\\__init__.py:88: in import_module\n    return _bootstrap._gcd_import(name[level:], package, level)\n           ^^^^^^^^^^^^^^^^^^^^^^^^^^^^^^^^^^^^^^^^^^^^^^^^^^^^\n<frozen importlib._bootstrap>:1387: in _gcd_import\n    ???\n<frozen importlib._bootstrap>:1360: in _find_and_load\n    ???\n<frozen importlib._bootstrap>:1331: in _find_and_load_unlocked\n    ???\n<frozen importlib._bootstrap>:935: in _load_unlocked\n    ???\n..\\..\\..\\..\\AppData\\Local\\Programs\\Python\\Python313\\Lib\\site-packages\\_pytest\\assertion\\rewrite.py:177: in exec_module\n    source_stat, co = _rewrite_test(fn, self.config)\n                      ^^^^^^^^^^^^^^^^^^^^^^^^^^^^^^\n..\\..\\..\\..\\AppData\\Local\\Programs\\Python\\Python313\\Lib\\site-packages\\_pytest\\assertion\\rewrite.py:357: in _rewrite_test\n    tree = ast.parse(source, filename=strfn)\n           ^^^^^^^^^^^^^^^^^^^^^^^^^^^^^^^^^\n..\\..\\..\\..\\AppData\\Local\\Programs\\Python\\Python313\\Lib\\ast.py:50: in parse\n    return compile(source, filename, mode, flags,\nE     File \"C:\\Users\\mezac\\Documents\\projects\\job\\Exam_Grader\\tests\\system\\test_training_system.py\", line 200\nE       f test_file_upload_validation(self, authenticated_client, test_user):\nE         ^^^^^^^^^^^^^^^^^^^^^^^^^^^\nE   SyntaxError: invalid syntax\n------------------------------- Captured stderr -------------------------------\nWARNING - Migrated deprecated environment variable: DEEPSEEK_SEED -> DEEPSEEK_RANDOM_SEED\nINFO - Migrated 1 deprecated environment variables\nINFO - Configuration loaded successfully with no warnings\nWARNING - Generated temporary master key. Set SECRETS_MASTER_KEY environment variable for production.\nERROR - Failed to load secrets: \nINFO - Loaded processing configuration from config/processing.json\nINFO - Loaded processing configuration from config/processing.json\nINFO - Added log handler: file_handler\nINFO - Added log handler: error_file_handler\nINFO - Added log handler: metrics\nINFO - Log handlers configured from ProcessingConfigManager\nINFO - Registered fallback method 'tesseract_ocr' for operation 'ocr_processing' with priority 1\nINFO - Registered fallback method 'easyocr_fallback' for operation 'ocr_processing' with priority 2\nINFO - Registered fallback method 'basic_text_extraction' for operation 'ocr_processing' with priority 3\nINFO - Registered fallback method 'cached_response' for operation 'llm_processing' with priority 1\nINFO - Registered fallback method 'template_response' for operation 'llm_processing' with priority 2\nINFO - Registered fallback method 'rule_based_processing' for operation 'llm_processing' with priority 3\nINFO - Registered fallback method 'alternative_library' for operation 'file_processing' with priority 1\nINFO - Registered fallback method 'basic_text_read' for operation 'file_processing' with priority 2\nINFO - Registered fallback method 'keyword_matching' for operation 'mapping_service' with priority 1\nINFO - Registered fallback method 'simple_mapping' for operation 'mapping_service' with priority 2\nINFO - Registered fallback method 'cached_grading' for operation 'grading_service' with priority 1\nINFO - Registered fallback method 'rule_based_grading' for operation 'grading_service' with priority 2\nINFO - Registered fallback method 'length_based_grading' for operation 'grading_service' with priority 3\n============================== warnings summary ===============================\n..\\..\\..\\..\\AppData\\Local\\Programs\\Python\\Python313\\Lib\\site-packages\\PyPDF2\\__init__.py:21\n  C:\\Users\\mezac\\AppData\\Local\\Programs\\Python\\Python313\\Lib\\site-packages\\PyPDF2\\__init__.py:21: DeprecationWarning: PyPDF2 is deprecated. Please move to the pypdf library instead.\n    warnings.warn(\n\n<string>:9\n  <string>:9: DeprecationWarning: datetime.datetime.utcnow() is deprecated and scheduled for removal in a future version. Use timezone-aware objects to represent datetimes in UTC: datetime.datetime.now(datetime.UTC).\n\n-- Docs: https://docs.pytest.org/en/stable/how-to/capture-warnings.html\n=========================== short test summary info ===========================\nERROR tests/system/test_training_system.py\n!!!!!!!!!!!!!!!!!!! Interrupted: 1 error during collection !!!!!!!!!!!!!!!!!!!!\n======================== 2 warnings, 1 error in 2.09s =========================\n","stderr":""},"Performance Tests":{"name":"Performance Tests","path":"tests/performance/test_training_performance.py","duration":22.806087493896484,"return_code":2,"passed":0,"failed":0,"skipped":0,"errors":0,"total":0,"success_rate":0,"stdout":"============================= test session starts =============================\nplatform win32 -- Python 3.13.4, pytest-8.4.1, pluggy-1.6.0 -- C:\\Users\\mezac\\AppData\\Local\\Programs\\Python\\Python313\\python.exe\ncachedir: .pytest_cache\nrootdir: C:\\Users\\mezac\\Documents\\projects\\job\\Exam_Grader\nconfigfile: pytest.ini\nplugins: anyio-4.9.0, cov-6.2.1\ncollecting ... collected 0 items / 1 error\n\n=================================== ERRORS ====================================\n_______ ERROR collecting tests/performance/test_training_performance.py _______\n..\\..\\..\\..\\AppData\\Local\\Programs\\Python\\Python313\\Lib\\site-packages\\_pytest\\python.py:498: in importtestmodule\n    mod = import_path(\n..\\..\\..\\..\\AppData\\Local\\Programs\\Python\\Python313\\Lib\\site-packages\\_pytest\\pathlib.py:587: in import_path\n    importlib.import_module(module_name)\n..\\..\\..\\..\\AppData\\Local\\Programs\\Python\\Python313\\Lib\\importlib\\__init__.py:88: in import_module\n    return _bootstrap._gcd_import(name[level:], package, level)\n           ^^^^^^^^^^^^^^^^^^^^^^^^^^^^^^^^^^^^^^^^^^^^^^^^^^^^\n<frozen importlib._bootstrap>:1387: in _gcd_import\n    ???\n<frozen importlib._bootstrap>:1360: in _find_and_load\n    ???\n<frozen importlib._bootstrap>:1331: in _find_and_load_unlocked\n    ???\n<frozen importlib._bootstrap>:935: in _load_unlocked\n    ???\n..\\..\\..\\..\\AppData\\Local\\Programs\\Python\\Python313\\Lib\\site-packages\\_pytest\\assertion\\rewrite.py:186: in exec_module\n    exec(co, module.__dict__)\ntests\\performance\\test_training_performance.py:15: in <module>\n    from webapp.app import create_app\nwebapp\\app.py:68: in <module>\n    app = main()\n          ^^^^^^\nwebapp\\app.py:47: in main\n    app = create_app()\n          ^^^^^^^^^^^^\nwebapp\\app_factory.py:57: in create_app\n    _register_blueprints(app)\nwebapp\\app_factory.py:175: in _register_blueprints\n    from webapp.routes.training_routes import training_bp\nE     File \"C:\\Users\\mezac\\Documents\\projects\\job\\Exam_Grader\\webapp\\routes\\training_routes.py\", line 868\nE       test_submission_ids = data.get('test_submission_ids', [])\\n        \nE                                                                 ^\nE   SyntaxError: unexpected character after line continuation character\n------------------------------- Captured stderr -------------------------------\nWARNING - Migrated deprecated environment variable: DEEPSEEK_SEED -> DEEPSEEK_RANDOM_SEED\nINFO - Migrated 1 deprecated environment variables\nINFO - Configuration loaded successfully with no warnings\nWARNING - Generated temporary master key. Set SECRETS_MASTER_KEY environment variable for production.\nERROR - Failed to load secrets: \nINFO - Loaded processing configuration from config/processing.json\nINFO - Loaded processing configuration from config/processing.json\nINFO - Added log handler: file_handler\nINFO - Added log handler: error_file_handler\nINFO - Added log handler: metrics\nINFO - Log handlers configured from ProcessingConfigManager\nINFO - Registered fallback method 'tesseract_ocr' for operation 'ocr_processing' with priority 1\nINFO - Registered fallback method 'easyocr_fallback' for operation 'ocr_processing' with priority 2\nINFO - Registered fallback method 'basic_text_extraction' for operation 'ocr_processing' with priority 3\nINFO - Registered fallback method 'cached_response' for operation 'llm_processing' with priority 1\nINFO - Registered fallback method 'template_response' for operation 'llm_processing' with priority 2\nINFO - Registered fallback method 'rule_based_processing' for operation 'llm_processing' with priority 3\nINFO - Registered fallback method 'alternative_library' for operation 'file_processing' with priority 1\nINFO - Registered fallback method 'basic_text_read' for operation 'file_processing' with priority 2\nINFO - Registered fallback method 'keyword_matching' for operation 'mapping_service' with priority 1\nINFO - Registered fallback method 'simple_mapping' for operation 'mapping_service' with priority 2\nINFO - Registered fallback method 'cached_grading' for operation 'grading_service' with priority 1\nINFO - Registered fallback method 'rule_based_grading' for operation 'grading_service' with priority 2\nINFO - Registered fallback method 'length_based_grading' for operation 'grading_service' with priority 3\nINFO - Configuration loaded successfully with no warnings\nINFO - Loaded processing configuration from config/processing.json\nINFO - Retry configurations loaded from ProcessingConfigManager\nINFO - ServiceRegistry initialized\nINFO - Loaded processing configuration from config/processing.json\nINFO - Initialized LLM connection pool with 3 connections\nINFO - Using OpenAI library version: 1.93.3\nINFO - LLM service initialized successfully with model: deepseek-chat (test skipped)\nINFO - Consolidated OCR service initialized successfully\nINFO - Added data collector: system_health\nINFO - Added data collector: performance\nINFO - Added data collector: error_tracking\nINFO - Added dashboard: System Health\nINFO - Added dashboard: Performance Metrics\nINFO - Added dashboard: Error Tracking\nINFO - Loaded processing configuration from config/processing.json\nINFO - Configured notification channels: ['log', 'email', 'webhook']\nINFO - Enhanced alerting system initialized\nINFO - Loaded processing configuration from config/processing.json\nINFO - Added cache level: l1_memory (memory)\nINFO - Added cache level: l2_memory (memory)\nINFO - Added cache level: l3_disk (disk)\nINFO - Added cache level: l4_hybrid (hybrid)\nINFO - Cache levels configured from ProcessingConfigManager\nINFO - Started cache cleanup thread\nINFO - Loaded processing configuration from config/processing.json\nINFO - Real-time metrics collector initialized (interval: 120s)\nERROR - Failed to start application: unexpected character after line continuation character (training_routes.py, line 868)\n============================== warnings summary ===============================\n..\\..\\..\\..\\AppData\\Local\\Programs\\Python\\Python313\\Lib\\site-packages\\PyPDF2\\__init__.py:21\n  C:\\Users\\mezac\\AppData\\Local\\Programs\\Python\\Python313\\Lib\\site-packages\\PyPDF2\\__init__.py:21: DeprecationWarning: PyPDF2 is deprecated. Please move to the pypdf library instead.\n    warnings.warn(\n\n<string>:9\n  <string>:9: DeprecationWarning: datetime.datetime.utcnow() is deprecated and scheduled for removal in a future version. Use timezone-aware objects to represent datetimes in UTC: datetime.datetime.now(datetime.UTC).\n\n-- Docs: https://docs.pytest.org/en/stable/how-to/capture-warnings.html\n=========================== short test summary info ===========================\nERROR tests/performance/test_training_performance.py\n!!!!!!!!!!!!!!!!!!! Interrupted: 1 error during collection !!!!!!!!!!!!!!!!!!!!\n======================== 2 warnings, 1 error in 10.51s ========================\n","stderr":""},"Security Tests":{"name":"Security Tests","path":"tests/security/test_training_security.py","duration":23.02124261856079,"return_code":2,"passed":0,"failed":0,"skipped":0,"errors":0,"total":0,"success_rate":0,"stdout":"============================= test session starts =============================\nplatform win32 -- Python 3.13.4, pytest-8.4.1, pluggy-1.6.0 -- C:\\Users\\mezac\\AppData\\Local\\Programs\\Python\\Python313\\python.exe\ncachedir: .pytest_cache\nrootdir: C:\\Users\\mezac\\Documents\\projects\\job\\Exam_Grader\nconfigfile: pytest.ini\nplugins: anyio-4.9.0, cov-6.2.1\ncollecting ... collected 0 items / 1 error\n\n=================================== ERRORS ====================================\n__________ ERROR collecting tests/security/test_training_security.py __________\n..\\..\\..\\..\\AppData\\Local\\Programs\\Python\\Python313\\Lib\\site-packages\\_pytest\\python.py:498: in importtestmodule\n    mod = import_path(\n..\\..\\..\\..\\AppData\\Local\\Programs\\Python\\Python313\\Lib\\site-packages\\_pytest\\pathlib.py:587: in import_path\n    importlib.import_module(module_name)\n..\\..\\..\\..\\AppData\\Local\\Programs\\Python\\Python313\\Lib\\importlib\\__init__.py:88: in import_module\n    return _bootstrap._gcd_import(name[level:], package, level)\n           ^^^^^^^^^^^^^^^^^^^^^^^^^^^^^^^^^^^^^^^^^^^^^^^^^^^^\n<frozen importlib._bootstrap>:1387: in _gcd_import\n    ???\n<frozen importlib._bootstrap>:1360: in _find_and_load\n    ???\n<frozen importlib._bootstrap>:1331: in _find_and_load_unlocked\n    ???\n<frozen importlib._bootstrap>:935: in _load_unlocked\n    ???\n..\\..\\..\\..\\AppData\\Local\\Programs\\Python\\Python313\\Lib\\site-packages\\_pytest\\assertion\\rewrite.py:186: in exec_module\n    exec(co, module.__dict__)\ntests\\security\\test_training_security.py:15: in <module>\n    from webapp.app import create_app\nwebapp\\app.py:68: in <module>\n    app = main()\n          ^^^^^^\nwebapp\\app.py:47: in main\n    app = create_app()\n          ^^^^^^^^^^^^\nwebapp\\app_factory.py:57: in create_app\n    _register_blueprints(app)\nwebapp\\app_factory.py:175: in _register_blueprints\n    from webapp.routes.training_routes import training_bp\nE     File \"C:\\Users\\mezac\\Documents\\projects\\job\\Exam_Grader\\webapp\\routes\\training_routes.py\", line 868\nE       test_submission_ids = data.get('test_submission_ids', [])\\n        \nE                                                                 ^\nE   SyntaxError: unexpected character after line continuation character\n------------------------------- Captured stderr -------------------------------\nWARNING - Migrated deprecated environment variable: DEEPSEEK_SEED -> DEEPSEEK_RANDOM_SEED\nINFO - Migrated 1 deprecated environment variables\nINFO - Configuration loaded successfully with no warnings\nWARNING - Generated temporary master key. Set SECRETS_MASTER_KEY environment variable for production.\nERROR - Failed to load secrets: \nINFO - Loaded processing configuration from config/processing.json\nINFO - Loaded processing configuration from config/processing.json\nINFO - Added log handler: file_handler\nINFO - Added log handler: error_file_handler\nINFO - Added log handler: metrics\nINFO - Log handlers configured from ProcessingConfigManager\nINFO - Registered fallback method 'tesseract_ocr' for operation 'ocr_processing' with priority 1\nINFO - Registered fallback method 'easyocr_fallback' for operation 'ocr_processing' with priority 2\nINFO - Registered fallback method 'basic_text_extraction' for operation 'ocr_processing' with priority 3\nINFO - Registered fallback method 'cached_response' for operation 'llm_processing' with priority 1\nINFO - Registered fallback method 'template_response' for operation 'llm_processing' with priority 2\nINFO - Registered fallback method 'rule_based_processing' for operation 'llm_processing' with priority 3\nINFO - Registered fallback method 'alternative_library' for operation 'file_processing' with priority 1\nINFO - Registered fallback method 'basic_text_read' for operation 'file_processing' with priority 2\nINFO - Registered fallback method 'keyword_matching' for operation 'mapping_service' with priority 1\nINFO - Registered fallback method 'simple_mapping' for operation 'mapping_service' with priority 2\nINFO - Registered fallback method 'cached_grading' for operation 'grading_service' with priority 1\nINFO - Registered fallback method 'rule_based_grading' for operation 'grading_service' with priority 2\nINFO - Registered fallback method 'length_based_grading' for operation 'grading_service' with priority 3\nINFO - Configuration loaded successfully with no warnings\nINFO - Loaded processing configuration from config/processing.json\nINFO - Retry configurations loaded from ProcessingConfigManager\nINFO - ServiceRegistry initialized\nINFO - Loaded processing configuration from config/processing.json\nINFO - Initialized LLM connection pool with 3 connections\nINFO - Using OpenAI library version: 1.93.3\nINFO - LLM service initialized successfully with model: deepseek-chat (test skipped)\nINFO - Consolidated OCR service initialized successfully\nINFO - Added data collector: system_health\nINFO - Added data collector: performance\nINFO - Added data collector: error_tracking\nINFO - Added dashboard: System Health\nINFO - Added dashboard: Performance Metrics\nINFO - Added dashboard: Error Tracking\nINFO - Loaded processing configuration from config/processing.json\nINFO - Configured notification channels: ['log', 'email', 'webhook']\nINFO - Enhanced alerting system initialized\nINFO - Loaded processing configuration from config/processing.json\nINFO - Added cache level: l1_memory (memory)\nINFO - Added cache level: l2_memory (memory)\nINFO - Added cache level: l3_disk (disk)\nINFO - Added cache level: l4_hybrid (hybrid)\nINFO - Cache levels configured from ProcessingConfigManager\nINFO - Started cache cleanup thread\nINFO - Loaded processing configuration from config/processing.json\nINFO - Real-time metrics collector initialized (interval: 120s)\nERROR - Failed to start application: unexpected character after line continuation character (training_routes.py, line 868)\n============================== warnings summary ===============================\n..\\..\\..\\..\\AppData\\Local\\Programs\\Python\\Python313\\Lib\\site-packages\\PyPDF2\\__init__.py:21\n  C:\\Users\\mezac\\AppData\\Local\\Programs\\Python\\Python313\\Lib\\site-packages\\PyPDF2\\__init__.py:21: DeprecationWarning: PyPDF2 is deprecated. Please move to the pypdf library instead.\n    warnings.warn(\n\n<string>:9\n  <string>:9: DeprecationWarning: datetime.datetime.utcnow() is deprecated and scheduled for removal in a future version. Use timezone-aware objects to represent datetimes in UTC: datetime.datetime.now(datetime.UTC).\n\n-- Docs: https://docs.pytest.org/en/stable/how-to/capture-warnings.html\n=========================== short test summary info ===========================\nERROR tests/security/test_training_security.py\n!!!!!!!!!!!!!!!!!!! Interrupted: 1 error during collection !!!!!!!!!!!!!!!!!!!!\n======================== 2 warnings, 1 error in 11.16s ========================\n","stderr":""},"Accessibility Tests":{"name":"Accessibility Tests","path":"tests/accessibility/test_training_accessibility.py","duration":30.71547031402588,"return_code":2,"passed":0,"failed":0,"skipped":0,"errors":0,"total":0,"success_rate":0,"stdout":"============================= test session starts =============================\nplatform win32 -- Python 3.13.4, pytest-8.4.1, pluggy-1.6.0 -- C:\\Users\\mezac\\AppData\\Local\\Programs\\Python\\Python313\\python.exe\ncachedir: .pytest_cache\nrootdir: C:\\Users\\mezac\\Documents\\projects\\job\\Exam_Grader\nconfigfile: pytest.ini\nplugins: anyio-4.9.0, cov-6.2.1\ncollecting ... collected 0 items / 1 error\n\n=================================== ERRORS ====================================\n_____ ERROR collecting tests/accessibility/test_training_accessibility.py _____\n..\\..\\..\\..\\AppData\\Local\\Programs\\Python\\Python313\\Lib\\site-packages\\_pytest\\python.py:498: in importtestmodule\n    mod = import_path(\n..\\..\\..\\..\\AppData\\Local\\Programs\\Python\\Python313\\Lib\\site-packages\\_pytest\\pathlib.py:587: in import_path\n    importlib.import_module(module_name)\n..\\..\\..\\..\\AppData\\Local\\Programs\\Python\\Python313\\Lib\\importlib\\__init__.py:88: in import_module\n    return _bootstrap._gcd_import(name[level:], package, level)\n           ^^^^^^^^^^^^^^^^^^^^^^^^^^^^^^^^^^^^^^^^^^^^^^^^^^^^\n<frozen importlib._bootstrap>:1387: in _gcd_import\n    ???\n<frozen importlib._bootstrap>:1360: in _find_and_load\n    ???\n<frozen importlib._bootstrap>:1331: in _find_and_load_unlocked\n    ???\n<frozen importlib._bootstrap>:935: in _load_unlocked\n    ???\n..\\..\\..\\..\\AppData\\Local\\Programs\\Python\\Python313\\Lib\\site-packages\\_pytest\\assertion\\rewrite.py:186: in exec_module\n    exec(co, module.__dict__)\ntests\\accessibility\\test_training_accessibility.py:13: in <module>\n    from webapp.app import create_app\nwebapp\\app.py:68: in <module>\n    app = main()\n          ^^^^^^\nwebapp\\app.py:47: in main\n    app = create_app()\n          ^^^^^^^^^^^^\nwebapp\\app_factory.py:57: in create_app\n    _register_blueprints(app)\nwebapp\\app_factory.py:175: in _register_blueprints\n    from webapp.routes.training_routes import training_bp\nE     File \"C:\\Users\\mezac\\Documents\\projects\\job\\Exam_Grader\\webapp\\routes\\training_routes.py\", line 868\nE       test_submission_ids = data.get('test_submission_ids', [])\\n        \nE                                                                 ^\nE   SyntaxError: unexpected character after line continuation character\n------------------------------- Captured stderr -------------------------------\nWARNING - Migrated deprecated environment variable: DEEPSEEK_SEED -> DEEPSEEK_RANDOM_SEED\nINFO - Migrated 1 deprecated environment variables\nINFO - Configuration loaded successfully with no warnings\nWARNING - Generated temporary master key. Set SECRETS_MASTER_KEY environment variable for production.\nERROR - Failed to load secrets: \nINFO - Loaded processing configuration from config/processing.json\nINFO - Loaded processing configuration from config/processing.json\nINFO - Added log handler: file_handler\nINFO - Added log handler: error_file_handler\nINFO - Added log handler: metrics\nINFO - Log handlers configured from ProcessingConfigManager\nINFO - Registered fallback method 'tesseract_ocr' for operation 'ocr_processing' with priority 1\nINFO - Registered fallback method 'easyocr_fallback' for operation 'ocr_processing' with priority 2\nINFO - Registered fallback method 'basic_text_extraction' for operation 'ocr_processing' with priority 3\nINFO - Registered fallback method 'cached_response' for operation 'llm_processing' with priority 1\nINFO - Registered fallback method 'template_response' for operation 'llm_processing' with priority 2\nINFO - Registered fallback method 'rule_based_processing' for operation 'llm_processing' with priority 3\nINFO - Registered fallback method 'alternative_library' for operation 'file_processing' with priority 1\nINFO - Registered fallback method 'basic_text_read' for operation 'file_processing' with priority 2\nINFO - Registered fallback method 'keyword_matching' for operation 'mapping_service' with priority 1\nINFO - Registered fallback method 'simple_mapping' for operation 'mapping_service' with priority 2\nINFO - Registered fallback method 'cached_grading' for operation 'grading_service' with priority 1\nINFO - Registered fallback method 'rule_based_grading' for operation 'grading_service' with priority 2\nINFO - Registered fallback method 'length_based_grading' for operation 'grading_service' with priority 3\nINFO - Configuration loaded successfully with no warnings\nINFO - Loaded processing configuration from config/processing.json\nINFO - Retry configurations loaded from ProcessingConfigManager\nINFO - ServiceRegistry initialized\nINFO - Loaded processing configuration from config/processing.json\nINFO - Initialized LLM connection pool with 3 connections\nINFO - Using OpenAI library version: 1.93.3\nINFO - LLM service initialized successfully with model: deepseek-chat (test skipped)\nINFO - Consolidated OCR service initialized successfully\nINFO - Added data collector: system_health\nINFO - Added data collector: performance\nINFO - Added data collector: error_tracking\nINFO - Added dashboard: System Health\nINFO - Added dashboard: Performance Metrics\nINFO - Added dashboard: Error Tracking\nINFO - Loaded processing configuration from config/processing.json\nINFO - Configured notification channels: ['log', 'email', 'webhook']\nINFO - Enhanced alerting system initialized\nINFO - Loaded processing configuration from config/processing.json\nINFO - Added cache level: l1_memory (memory)\nINFO - Added cache level: l2_memory (memory)\nINFO - Added cache level: l3_disk (disk)\nINFO - Added cache level: l4_hybrid (hybrid)\nINFO - Cache levels configured from ProcessingConfigManager\nINFO - Started cache cleanup thread\nINFO - Loaded processing configuration from config/processing.json\nINFO - Real-time metrics collector initialized (interval: 120s)\nERROR - Failed to start application: unexpected character after line continuation character (training_routes.py, line 868)\n============================== warnings summary ===============================\n..\\..\\..\\..\\AppData\\Local\\Programs\\Python\\Python313\\Lib\\site-packages\\PyPDF2\\__init__.py:21\n  C:\\Users\\mezac\\AppData\\Local\\Programs\\Python\\Python313\\Lib\\site-packages\\PyPDF2\\__init__.py:21: DeprecationWarning: PyPDF2 is deprecated. Please move to the pypdf library instead.\n    warnings.warn(\n\n<string>:9\n  <string>:9: DeprecationWarning: datetime.datetime.utcnow() is deprecated and scheduled for removal in a future version. Use timezone-aware objects to represent datetimes in UTC: datetime.datetime.now(datetime.UTC).\n\n-- Docs: https://docs.pytest.org/en/stable/how-to/capture-warnings.html\n=========================== short test summary info ===========================\nERROR tests/accessibility/test_training_accessibility.py\n!!!!!!!!!!!!!!!!!!! Interrupted: 1 error during collection !!!!!!!!!!!!!!!!!!!!\n======================== 2 warnings, 1 error in 15.32s ========================\n","stderr":""}},"requirements_coverage":{"file_upload_management":{"covered":false,"test_suites":["System Tests","Security Tests"],"confidence":"Medium"},"llm_guide_analysis":{"covered":false,"test_suites":["Integration Tests","Unit Tests"],"confidence":"Medium"},"training_configuration":{"covered":false,"test_suites":["Training Service Unit Tests","System Tests"],"confidence":"Medium"},"session_management":{"covered":false,"test_suites":["Database Models Unit Tests","System Tests"],"confidence":"Medium"},"report_generation":{"covered":false,"test_suites":["Report Service Unit Tests","System Tests"],"confidence":"Medium"},"model_testing":{"covered":false,"test_suites":["System Tests","Integration Tests"],"confidence":"Medium"},"confidence_monitoring":{"covered":false,"test_suites":["System Tests","Unit Tests"],"confidence":"Medium"},"security_file_management":{"covered":false,"test_suites":["Security Tests","System Tests"],"confidence":"Medium"},"accessibility":{"covered":false,"test_suites":["Accessibility Tests"],"confidence":"Medium"},"performance":{"covered":false,"test_suites":["Performance Tests"],"confidence":"Medium"}},"recommendations":["❌ No tests were executed. Ensure test files exist and are properly configured.","❌ Database Models Unit Tests failed to run properly. Check test configuration and dependencies.","❌ Training Service Unit Tests failed to run properly. Check test configuration and dependencies.","❌ Report Service Unit Tests failed to run properly. Check test configuration and dependencies.","❌ Integration Tests failed to run properly. Check test configuration and dependencies.","❌ System Tests failed to run properly. Check test configuration and dependencies.","❌ Performance Tests failed to run properly. Check test configuration and dependencies.","❌ Security Tests failed to run properly. Check test configuration and dependencies.","❌ Accessibility Tests failed to run properly. Check test configuration and dependencies."]}